Workbook

Sheet README
A1: Task Buddy - Delivery Blueprint Workbook
A2: AI-powered to-do app for React Native + Expo. Generated with the /delivery-blueprint workflow. Project key: TB.
A4: At a glance (live formulas)
A5: Stories in backlog | B5: =COUNTA('Product Backlog'!A2:A68) -> 67
A6: Total story points | B6: =SUM('Product Backlog'!H2:H68) -> 279
A7: MVP points (Phase = MVP) | B7: =SUMIFS('Product Backlog'!H2:H68,'Product Backlog'!L2:L68,"MVP") -> 58
A8: Planned sprints | B8: =MAX('Product Backlog'!K2:K68) -> 10
A9: Sprint capacity (points/sprint) - input | B9: 30
A10: Sprint 1 start date - input | B10: 46328
A12: Legends
A13: Status flow | B13: Draft > Ready > In Progress > Blocked > Code Review > QA Testing > UAT > Done
A14: Priority | B14: P0 critical path (Highest) | P1 high | P2 medium | P3 nice-to-have (Low)
A15: Points | B15: Fibonacci (1,2,3,5,8). Stories above 8 must be split.
A16: Waves | B16: Sequence bands derived from the dependency-ordered sprint plan; workstreams run in parallel inside a wave.
A17: Branch | B17: <type>/tb-<ticket>/<short-kebab-title> e.g. feat/tb-015/quick-add-preview
A18: Commit | B18: Conventional Commits: feat(capture): add parse preview (TB-015)
A19: Blue text | B19: Input cell you can change (capacity, start date); totals recalculate.
A21: Waves
A22: Wave 1 - Foundations & Identity | B22: Repo, tooling, design system, local data layer, Supabase, sign-in
A23: Wave 2 - Task Core + AI Gateway & Guardrails | B23: Task CRUD/screens plus the AI gateway with rate limits, quotas, output contracts and injection hardening
A24: Wave 3 - Core AI Value | B24: Natural-language capture, task breakdown, smart daily plan, beta distribution
A25: Wave 4 - Retain & Engage | B25: Notifications, buddy check-ins, sync, recurring tasks, procrastination helper, onboarding, compliance
A26: Wave 5 - Channels & Intelligence | B26: Buddy chat, voice, photo, weekly review, accessibility, v1.0 store release
A27: Wave 6 - Platform & Ecosystem | B27: Shared Spaces (multiplayer AI), billing, calendar, widgets, on-device AI
A29: Workstreams
A30: WS-A | B30: Mobile App (UI & UX)
A31: WS-B | B31: Data, Auth & Sync
A32: WS-C | B32: AI & Backend (Edge Functions)
A33: WS-D | B33: Platform, DevOps & Release
A34: WS-E | B34: Quality & Accessibility
A36: Tabs
A37: Project Overview
A38: Product Roadmap
A39: Epic Backlog
A40: Feature Backlog
A41: Product Backlog
A42: Sprint Backlog
A43: Technical Backlog
A44: Architecture & Decisions
A45: Data Model
...

Sheet Project Overview
A1: Item | B1: Detail
A2: Product | B2: Task Buddy - an AI to-do app that turns sentences, voice and photos into organized, scheduled tasks and nudges you to finish them.
A3: Summary | B3: Local-first React Native (Expo) app. A server-side AI gateway handles capture parsing, task breakdown, daily planning, check-ins, chat and weekly review. Later phases add voice/photo, Shared Spaces where people and an AI agent collaborate, billing, calendar, widgets and optional on-device AI.
A4: Objectives | B4: 1) MVP in about 2 weeks: sign in, tasks, natural-language capture, AI breakdown. 2) v1.0 store release by Sprint 7 with plan, reminders, check-ins, voice/photo, weekly review, compliance. 3) Shared Spaces (multiplayer AI) and Pro tier in Phase 3.
A5: Target users | B5: Busy individuals who capture tasks in messy language (English/Taglish), students and young professionals, and later small teams/families sharing a space.
A6: KPI (proposed targets) | B6: Activation: first AI-created task within 24h of signup >= 60% AI parse accuracy on golden set >= 90% AI p95 latency < 6 s (parse/breakdown) Crash-free sessions >= 99.5% D7 retention >= 25% AI cost per active user per month under a budget set after 4 weeks of ledger data
A7: Constraints | B7: Solo developer with AI coding agents; 30 pts/sprint; LLM key server-side only; works offline for core task use; store policy compliance (account deletion, AI disclosure).
A8: Assumptions | B8: See 'Gaps & Assumptions' tab.
A9: Top risks | B9: See 'Risk Register' tab: AI cost, prompt injection, sync data loss, store rejection, solo capacity.
A10: Stack (locked) | B10: Expo + RN + TypeScript, Expo Router, NativeWind, Zustand + TanStack Query, RHF + Zod, expo-sqlite + Drizzle, Supabase (Auth/Postgres/Realtime/Storage/Edge Functions), Claude via gateway, expo-notifications, expo-speech-recognition, RevenueCat, Sentry, PostHog, Jest + RNTL + Maestro, GitHub Actions + EAS.

Sheet Product Roadmap
A1: Phase | B1: Sprints | C1: Start | D1: End | E1: Goal | F1: Key outcomes | G1: Points | H1: Priority focus | I1: Dependencies | J1: Release target
A2: MVP | B2: Sprint 1-2 | C2: 46328 | D2: 46339 | E2: Capture and breakdown on a solid base | F2: Sign in, tasks, quick-add, AI breakdown, AI gateway with guardrails | G2: 60 | H2: P0/P1 | I2: See Epic Backlog | J2: Internal MVP
A3: Phase 2a - Beta | B3: Sprint 3-5 | C3: 46342 | D3: 46360 | E3: Plan, retain and engage | F3: Daily plan, undo, evals, TestFlight/Play beta, reminders, sync, lists, recurring, push, check-ins, onboarding, E2E | G3: 84 | H3: P0/P1 | I3: See Epic Backlog | J3: Private beta (Sprint 3 onward)
A4: Phase 2b - v1.0 | B4: Sprint 6-7 | C4: 46363 | D4: 46374 | E4: Channels, intelligence and launch | F4: Compliance, buddy chat, voice, photo, weekly review, accessibility, performance, analytics | G4: 56 | H4: P1/P2 | I4: See Epic Backlog | J4: v1.0 store release (end Sprint 7)
A5: Phase 3 - Platform | B5: Sprint 8-10 | C5: 46377 | D5: 46395 | E5: Shared Spaces and monetization | F5: Spaces, shared lists, shared AI agent with permissions and audit, billing, calendar, widgets, on-device AI | G5: 79 | H5: P1/P2 | I5: See Epic Backlog | J5: Spaces beta (Sprint 9), Pro tier (Sprint 10)

Sheet Epic Backlog
A1: Epic ID | B1: Name | C1: Description | D1: Business Value | E1: Priority | F1: Waves | G1: Dependencies | H1: Acceptance Criteria | I1: Stories | J1: Points | K1: Status
A2: EP-01 | B2: Foundations & DevOps | C2: Repository, tooling, CI/CD, design system and navigation shell. | D2: Every later story depends on a consistent, testable, shippable base. | E2: P0 | F2: 1 | G2: - | H2: Clean clone boots on iOS+Android; CI green on PR; dev-client build installs. | I2: =COUNTIF('Product Backlog'!B2:B68,A2) -> 4 | J2: =SUMIFS('Product Backlog'!H2:H68,'Product Backlog'!B2:B68,A2) -> 11 | K2: Draft
A3: EP-02 | B3: Auth & Accounts | C3: Supabase backend baseline, email OTP and social sign-in, settings. | D3: Identity is required for AI quotas, sync, push and shared spaces. | E3: P0 | F3: 1 | G3: EP-01 | H3: User can sign in/out; sessions persist; RLS blocks cross-user reads. | I3: =COUNTIF('Product Backlog'!B2:B68,A3) -> 4 | J3: =SUMIFS('Product Backlog'!H2:H68,'Product Backlog'!B2:B68,A3) -> 10 | K3: Draft
A4: EP-03 | B4: Task Core & Sync | C4: Local-first task data, CRUD screens, lists/tags/search, recurring tasks, offline sync. | D4: The app is a to-do list first; it must be fast, offline-capable and reliable. | E4: P0 | F4: 1-4 | G4: EP-01 | H4: Tasks work fully offline; sync converges across two devices with no data loss. | I4: =COUNTIF('Product Backlog'!B2:B68,A4) -> 8 | J4: =SUMIFS('Product Backlog'!H2:H68,'Product Backlog'!B2:B68,A4) -> 37 | K4: Draft
A5: EP-04 | B5: AI Gateway & Guardrails | C5: Single Edge Function gateway to the LLM with auth, rate limits, quotas, output contracts, injection hardening, optional on-device inference. | D5: Keeps API keys off devices, caps cost, and makes AI output safe and typed. | E5: P0 | F5: 2 | G5: EP-02 | H5: No AI call reaches the provider without auth, quota check and validated schema. | I5: =COUNTIF('Product Backlog'!B2:B68,A5) -> 5 | J5: =SUMIFS('Product Backlog'!H2:H68,'Product Backlog'!B2:B68,A5) -> 21 | K5: Draft
A6: EP-05 | B6: Natural-Language Capture | C6: Type a sentence, get structured tasks with dates, priorities and lists. | D6: Headline feature: capture friction drops to a single sentence. | E6: P0 | F6: 3 | G6: EP-03, EP-04 | H6: >=90% of golden-set sentences produce correct task count and due dates. | I6: =COUNTIF('Product Backlog'!B2:B68,A6) -> 3 | J6: =SUMIFS('Product Backlog'!H2:H68,'Product Backlog'!B2:B68,A6) -> 10 | K6: Draft
A7: EP-06 | B7: AI Task Breakdown | C7: Break a vague task into subtasks with time estimates. | D7: Turns overwhelming tasks into actionable steps; reduces procrastination. | E7: P1 | F7: 3 | G7: EP-03, EP-04 | H7: Breakdown returns 3-8 actionable subtasks the user can accept or regenerate. | I7: =COUNTIF('Product Backlog'!B2:B68,A7) -> 1 | J7: =SUMIFS('Product Backlog'!H2:H68,'Product Backlog'!B2:B68,A7) -> 5 | K7: Draft
A8: EP-07 | B8: Smart Daily Plan | C8: Work-hours settings, AI daily schedule, plan UI and re-planning on missed tasks. | D8: Daily habit loop: open app, see a realistic plan. | E8: P1 | F8: 3-4 | G8: EP-03, EP-04 | H8: Plan fits within available hours and respects due dates; re-plan after overdue. | I8: =COUNTIF('Product Backlog'!B2:B68,A8) -> 4 | J8: =SUMIFS('Product Backlog'!H2:H68,'Product Backlog'!B2:B68,A8) -> 19 | K8: Draft
A9: EP-08 | B9: Notifications & Buddy Check-ins | C9: Local reminders, permission flow, push infrastructure, contextual AI check-ins with quick actions. | D9: Retention engine; the 'buddy' personality lives here. | E9: P1 | F9: 4 | G9: EP-03, EP-04 | H9: Reminders fire on time offline; check-ins respect quiet hours and caps. | I9: =COUNTIF('Product Backlog'!B2:B68,A9) -> 4 | J9: =SUMIFS('Product Backlog'!H2:H68,'Product Backlog'!B2:B68,A9) -> 16 | K9: Draft
A10: EP-09 | B10: Procrastination Helper & Buddy Chat | C10: Detect repeatedly postponed tasks, suggest starter steps, chat assistant with confirmed actions, personality settings. | D10: Differentiator: the app helps you finish, not just list. | E10: P1 | F10: 4-5 | G10: EP-04, EP-08 | H10: Chat can propose add/complete/reschedule and only executes after user confirmation. | I10: =COUNTIF('Product Backlog'!B2:B68,A10) -> 4 | J10: =SUMIFS('Product Backlog'!H2:H68,'Product Backlog'!B2:B68,A10) -> 17 | K10: Draft
A11: EP-10 | B11: Voice & Photo Capture | C11: Voice-to-tasks via on-device speech recognition and photo-to-tasks via vision, with media privacy controls. | D11: Capture anywhere: hands-free and from handwritten lists. | E11: P1 | F11: 5 | G11: EP-05 | H11: Voice and photo feed the same review screen; raw media deleted within 24h. | I11: =COUNTIF('Product Backlog'!B2:B68,A11) -> 3 | J11: =SUMIFS('Product Backlog'!H2:H68,'Product Backlog'!B2:B68,A11) -> 13 | K11: Draft
A12: EP-11 | B12: Weekly Review & Insights | C12: Weekly stats and AI-written review of wins, slips and patterns. | D12: Reflection loop that builds long-term retention. | E12: P2 | F12: 5 | G12: EP-03, EP-04 | H12: Review generates in <15s from real stats and cites only real data. | I12: =COUNTIF('Product Backlog'!B2:B68,A12) -> 2 | J12: =SUMIFS('Product Backlog'!H2:H68,'Product Backlog'!B2:B68,A12) -> 8 | K12: Draft
A13: EP-12 | B13: Shared Spaces (Multiplayer AI) | C13: Shared spaces with members, realtime shared lists, assignment, a shared AI agent with scoped permissions and audit log. | D13: Strategic: humans and an AI agent collaborating in one shared space. | E13: P2 | F13: 6 | G13: EP-03, EP-04, EP-08 | H13: Two members see changes in <2s; agent actions are permissioned, confirmable and audited. | I13: =COUNTIF('Product Backlog'!B2:B68,A13) -> 9 | J13: =SUMIFS('Product Backlog'!H2:H68,'Product Backlog'!B2:B68,A13) -> 47 | K13: Draft
A14: EP-13 | B14: Monetization, Compliance & Release | C14: Beta distribution, onboarding, privacy/compliance, store release, billing tiers, calendar, widgets. | D14: Gets the app legally and commercially into users' hands. | E14: P0 | F14: 3-6 | G14: EP-01, EP-02 | H14: v1.0 passes store review; account deletion and data export work; Pro tier unlocks quotas. | I14: =COUNTIF('Product Backlog'!B2:B68,A14) -> 9 | J14: =SUMIFS('Product Backlog'!H2:H68,'Product Backlog'!B2:B68,A14) -> 41 | K14: Draft
A15: EP-14 | B15: Quality, Observability & Accessibility | C15: Crash reporting, E2E tests, AI evals, analytics, accessibility, i18n, performance. | D15: Keeps AI quality, stability and inclusivity measurable. | E15: P1 | F15: 3-5 | G15: EP-01 | H15: Crash-free sessions >=99.5%; AI eval suite gates CI; WCAG-aligned labels and dynamic type. | I15: =COUNTIF('Product Backlog'!B2:B68,A15) -> 7 | J15: =SUMIFS('Product Backlog'!H2:H68,'Product Backlog'!B2:B68,A15) -> 24 | K15: Draft

Sheet Feature Backlog
A1: Feature ID | B1: Epic | C1: Name | D1: Description | E1: Priority | F1: Complexity | G1: Dependencies | H1: Status
A2: FT-01 | B2: EP-01 | C2: Project scaffold & tooling | D2: Expo + TS + Router, lint, typecheck, aliases. | E2: P0 | F2: S | G2: - | H2: Draft
A3: FT-02 | B3: EP-01 | C3: CI/CD & build profiles | D3: GitHub Actions, EAS profiles, dev client. | E3: P0 | F3: S | G3: FT-01 | H3: Draft
A4: FT-03 | B4: EP-01 | C4: Design system & navigation shell | D4: Tokens, primitives, tab/modal shell. | E4: P0 | F4: M | G4: FT-01 | H4: Draft
A5: FT-06 | B5: EP-02 | C5: Supabase backend baseline | D5: Projects, env, RLS baseline, types. | E5: P0 | F5: S | G5: FT-01 | H5: Draft
A6: FT-04 | B6: EP-02 | C6: Email OTP sign-in | D6: OTP auth with secure session storage. | E6: P0 | F6: S | G6: FT-06 | H6: Draft
A7: FT-05 | B7: EP-02 | C7: Social sign-in | D7: Apple and Google sign-in. | E7: P2 | F7: S | G7: FT-04 | H7: Draft
A8: FT-49 | B8: EP-02 | C8: Settings & preferences | D8: Settings screen shell and preference store. | E8: P1 | F8: S | G8: FT-03 | H8: Draft
A9: FT-07 | B9: EP-03 | C9: Local data layer | D9: SQLite + Drizzle schema, migrations, repositories. | E9: P0 | F9: M | G9: FT-01 | H9: Draft
A10: FT-08 | B10: EP-03 | C10: Task management UI | D10: CRUD, Today/Inbox, task detail. | E10: P0 | F10: M | G10: FT-07 | H10: Draft
A11: FT-09 | B11: EP-03 | C11: Organization | D11: Lists, tags, filters, full-text search. | E11: P2 | F11: M | G11: FT-08 | H11: Draft
A12: FT-10 | B12: EP-03 | C12: Recurring tasks | D12: RRULE-based repetition. | E12: P2 | F12: M | G12: FT-08 | H12: Draft
... A50: FT-48 | B50: EP-14 | C50: Performance | D50: Startup and list performance budgets. | E50: P2 | F50: S | G50: FT-08 | H50: Draft

Sheet Product Backlog
A1: Story ID | B1: Epic | C1: Feature | D1: Title | E1: User Story | F1: Acceptance Criteria (testable) | G1: Priority | H1: Points | I1: Wave | J1: Workstream | K1: Sprint | L1: Phase | M1: Blocked By | N1: Status
A2: US-001 | B2: EP-01 | C2: FT-01 | D2: Scaffold Expo app (TypeScript, Router, lint, aliases) | E2: As a developer, I want a TypeScript Expo app scaffolded with Expo Router, strict TS, ESLint/Prettier and path aliases, so that every later story starts from one consistent base. | F2: - Given a fresh clone, when I run `pnpm install && pnpm start`, then the app boots on an iOS simulator and an Android emulator with a placeholder home route - Given the repo, when I run `pnpm lint && pnpm typecheck`, then both pass with zero errors in strict mode - The folder structure matches CLAUDE.md section 3 and `docs/tickets/_TEMPLATE.md` exists | G2: P0 | H2: 3 | I2: Wave 1 | J2: WS-D | K2: 1 | L2: MVP | M2: - | N2: Ready
A3: US-002 | B3: EP-01 | C3: FT-02 | D3: CI pipeline and EAS build profiles | E3: As a developer, I want CI and EAS build profiles, so that every PR is linted, typechecked, tested and installable as a dev client. | F3: - Given a PR, when it is opened, then GitHub Actions runs lint, typecheck and unit tests and finishes in under 8 minutes - Given `eas build --profile development`, then a dev-client build is produced and installs on a device or simulator - Branch protection requires green CI and one review before merge to main | G3: P0 | H3: 3 | I3: Wave 1 | J3: WS-D | K3: 1 | L3: MVP | M3: US-001 | N3: Ready
A4: US-003 | B4: EP-01 | C4: FT-03 | D4: Design system: theme tokens and UI primitives | E4: As a user, I want a consistent, accessible look in light and dark mode, so that the app feels polished and readable. | F4: - Given the system theme changes, when the app is open, then all primitives (Button, Input, Card, Checkbox, Sheet) switch theme without a reload - Colour tokens meet 4.5:1 contrast for body text in both themes - Each primitive has a typed props interface and is used by at least one screen (reuse-first) | G4: P0 | H4: 3 | I4: Wave 1 | J4: WS-A | K4: 1 | L4: MVP | M4: US-001 | N4: Ready
A5: US-004 | B5: EP-01 | C5: FT-03 | D5: App shell: tab navigation and task modal | E5: As a user, I want tab navigation (Today, Inbox, Buddy, Settings) and a task detail modal, so that I can move around the app quickly. | F5: - Given the app is open, when I tap each tab, then the matching screen renders in under 300 ms - Given the deep link `taskbuddy://task/<id>`, when opened, then the task detail modal is shown - The Android back gesture and iOS swipe-back close the modal without losing state | G5: P0 | H5: 2 | I5: Wave 1 | J5: WS-A | K5: 1 | L5: MVP | M5: US-003 | N5: Ready
A6: US-005 | B6: EP-02 | C6: FT-06 | D6: Supabase projects, env config and RLS baseline | E6: As a developer, I want Supabase dev/staging/prod projects with env config and RLS baseline, so that auth and data are secure from the first commit. | F6: - Given three Supabase projects, then URLs and anon keys are injected through EAS env and no service-role key exists in the client bundle - Given users A and B, when A queries B's profile row, then RLS returns zero rows (automated test) - TypeScript types are generated from the schema in CI and the build fails on drift | G6: P0 | H6: 2 | I6: Wave 1 | J6: WS-B | K6: 1 | L6: MVP | M6: US-001 | N6: Ready
A7: US-006 | B7: EP-02 | C7: FT-04 | D7: Email OTP sign-in with secure session | E7: As a user, I want to sign in with an emailed 6-digit code, so that I can use the app without remembering a password. | F7: - Given a valid email and correct code, when I submit, then I land on Today within 3 seconds and the session survives an app restart - Given a wrong or expired code, then an inline error is shown and I can request a new code after 30 seconds - Sessions are stored in expo-secure-store and refresh automatically; sign-out clears them | G7: P0 | H7: 3 | I7: Wave 1 | J7: WS-B | K7: 1 | L7: MVP | M7: US-005, US-004 | N7: Ready
A8: US-007 | B8: EP-03 | C8: FT-07 | D8: Local SQLite schema, migrations and repositories | E8: As a developer, I want a local SQLite schema with migrations and repositories, so that the app works offline and is ready for sync. | F8: - Given a first launch, then migrations run and tables tasks, subtasks, lists, tags exist with id (UUIDv7), updated_at and deleted_at - Given a v1 database with data, when v2 migration runs in a test, then no rows are lost - Given 10,000 tasks, a list query returns in under 50 ms at p95 on a mid-range Android device | G8: P0 | H8: 3 | I8: Wave 1 | J8: WS-B | K8: 1 | L8: MVP | M8: US-001 | N8: Ready
A9: US-008 | B9: EP-04 | C9: FT-12 | D9: AI gateway Edge Function with JWT auth | E9: As a developer, I want a Supabase Edge Function AI gateway that verifies the user JWT and calls the LLM through a provider interface, so that API keys never ship in the app. | F9: - Given an unauthenticated request, then the gateway returns 401 and never calls the provider - Given a valid request, then routes /parse, /breakdown, /plan use their configured model and a 20-second timeout - The provider API key exists only as an Edge Function secret and a search of the app bundle finds no key | G9: P0 | H9: 5 | I9: Wave 2 | J9: WS-C | K9: 1 | L9: MVP | M9: US-005, US-006 | N9: Ready
A10: US-009 | B10: EP-04 | C10: FT-13 | D10: Per-user AI rate limits and token quotas | E10: As the product owner, I want per-user rate limits and daily token quotas on every AI call, so that cost and abuse are capped from day one. | F10: - Given a free user, when they make a 31st AI call within an hour, then the gateway returns 429 with Retry-After and the app shows a friendly message - Every AI call writes a row to the usage ledger with user, route, model, input/output tokens and cost estimate - A daily token quota per user is enforced and the quota resets at 00:00 UTC | G10: P0 | H10: 3 | I10: Wave 2 | J10: WS-C | K10: 1 | L10: MVP | M10: US-008 | N10: Ready
A11: US-010 | B11: EP-04 | C11: FT-14 | D11: AI output schemas, validation and repair retry | E11: As a developer, I want JSON schemas and validation for every AI response, so that malformed model output never reaches the database. | F11: - Given 200 golden inputs, then at least 98% of responses validate against the schema after at most one automatic repair retry - Given invalid output after the retry, then the gateway returns the typed error AI_BAD_OUTPUT and nothing is persisted - Prompt templates are versioned in the repo and the version is logged with each request | G11: P0 | H11: 3 | I11: Wave 2 | J11: WS-C | K11: 1 | L11: MVP | M11: US-008 | N11: Ready
A12: US-011 | B12: EP-04 | C12: FT-14 | D12: Prompt-injection and input hardening | E12: As the product owner, I want input hardening against prompt injection, so that user text can never exfiltrate prompts or trigger actions. | F12: - Given a corpus of 20 injection prompts (e.g. 'ignore previous instructions'), then none returns the system prompt or triggers a tool action - Inputs over 2,000 characters are rejected with 413 and control characters are stripped - AI-proposed actions are never executed server-side; the client must confirm | G12: P0 | H12: 2 | I12: Wave 2 | J12: WS-C | K12: 2 | L12: MVP | M12: US-008 | N12: Ready
A13: US-012 | B13: EP-03 | C13: FT-08 | D13: Task CRUD with due date and priority | E13: As a user, I want to create, edit, complete and delete tasks with a due date and priority, so that I can manage my work. | F13: - Given the add-task form, when I save a title with due date and priority, then the task appears in the right list instantly (optimistic) and persists after restart - Given a task, when I complete it, then it moves to Completed with a timestamp and can be un-completed - Deleting a task is a soft delete (deleted_at) with a 5-second undo | G13: P0 | H13: 5 | I13: Wave 2 | J13: WS-A | K13: 2 | L13: MVP | M13: US-007, US-004 | N13: Ready
... A68: US-067 | B68: EP-04 | C68: FT-42 | D68: Experimental on-device parsing | E68: As a privacy-minded user, I want offline task parsing on my device, so that capture works without internet and without sending text. | F68: - Given airplane mode, then quick-add parses simple sentences locally and falls back to plain add when confidence is low - The local model download is optional, shows its size, and can be removed - On the golden set the local parser reaches at least 75% accuracy and the gap vs cloud is reported | G68: P3 | H68: 8 | I68: Wave 6 | J68: WS-C | K68: 10 | L68: Phase 3 | M68: US-016, US-010, US-025 | N68: Draft
G70: Total | H70: =SUM(H2:H68) -> 279

Sheet Sprint Backlog
A1: Sprint # | B1: Start | C1: End | D1: Goal | E1: Stories | F1: Est. Points | G1: Capacity | H1: Utilization | I1: Depends on (earlier sprints) | J1: Deliverables
A2: 1 | B2: 46328 | C2: 46332 | D2: Foundations: scaffold, CI, design system, shell, Supabase, email sign-in, local DB, and the AI gateway with rate limits and output contracts. | E2: US-001, US-002, US-003, US-004, US-005, US-006, US-007, US-008, US-009, US-010 | F2: =SUMIFS('Product Backlog'!H2:H68,'Product Backlog'!K2:K68,A2) -> 30 | G2: 30 | H2: =F2/G2 -> 1 | I2: - | J2: Bootable app, CI, design system, Supabase, email sign-in, local DB, AI gateway with limits and schemas
A3: 2 | B3: 46335 | C3: 46339 | D3: MVP complete: injection hardening, task CRUD and Today/Inbox/detail screens, natural-language quick-add, AI task breakdown, settings shell. | E3: US-011, US-012, US-013, US-014, US-015, US-016, US-017, US-018 | F3: =SUMIFS('Product Backlog'!H2:H68,'Product Backlog'!K2:K68,A3) -> 30 | G3: 30 | H3: =F3/G3 -> 1 | I3: US-004, US-007, US-008, US-009, US-010 | J3: Working MVP: tasks, Today/Inbox, quick-add parse, AI breakdown, settings shell
A4: 3 | B4: 46342 | C4: 46346 | D4: Daily plan (work hours, generation, plan UI), undo for AI tasks, crash reporting, first TestFlight/Play beta and AI evals. | E4: US-019, US-020, US-021, US-022, US-023, US-024, US-025 | F4: =SUMIFS('Product Backlog'!H2:H68,'Product Backlog'!K2:K68,A4) -> 28 | G4: 30 | H4: =F4/G4 -> 0.93333333 | I4: US-001, US-002, US-009, US-010, US-012, US-013, US-015, US-016, US-017, US-018 | J4: Daily plan, undo, Sentry, first beta build, eval harness
A5: 4 | B5: 46349 | C5: 46353 | D5: Retention: reminders, permission flow, re-plan, offline sync, lists/tags, recurring tasks. | E5: US-026, US-027, US-028, US-029, US-030, US-031 | F5: =SUMIFS('Product Backlog'!H2:H68,'Product Backlog'!K2:K68,A5) -> 27 | G5: 30 | H5: =F5/G5 -> 0.9 | I5: US-006, US-007, US-012, US-018, US-021 | J5: Reminders, offline sync, lists/tags, recurring, re-plan
A6: 5 | B6: 46356 | C6: 46360 | D6: Push infrastructure, buddy check-ins, procrastination helper, social sign-in, onboarding, E2E tests. | E6: US-032, US-033, US-034, US-035, US-036, US-037, US-038 | F6: =SUMIFS('Product Backlog'!H2:H68,'Product Backlog'!K2:K68,A6) -> 29 | G6: 30 | H6: =F6/G6 -> 0.96666667 | I6: US-002, US-006, US-008, US-009, US-010, US-013, US-014, US-015, US-018, US-019, US-020, US-026, US-027 | J6: Push + check-ins, procrastination helper, onboarding, E2E suite
A7: 6 | B7: 46363 | C7: 46367 | D7: Compliance and buddy chat: data export/deletion, privacy docs, chat, personality, voice, photo. | E7: US-039, US-040, US-041, US-042, US-043, US-044 | F7: =SUMIFS('Product Backlog'!H2:H68,'Product Backlog'!K2:K68,A7) -> 28 | G7: 30 | H7: =F7/G7 -> 0.93333333 | I7: US-006, US-008, US-009, US-010, US-011, US-012, US-015, US-016, US-018, US-029 | J7: Account deletion/export, privacy docs, buddy chat, voice, photo
A8: 7 | B8: 46370 | C8: 46374 | D8: Media privacy, weekly review, accessibility, performance, analytics, i18n and the v1.0 store release. | E8: US-045, US-046, US-047, US-048, US-049, US-050, US-051, US-052 | F8: =SUMIFS('Product Backlog'!H2:H68,'Product Backlog'!K2:K68,A8) -> 28 | G8: 30 | H8: =F8/G8 -> 0.93333333 | I8: US-004, US-009, US-010, US-013, US-014, US-015, US-018, US-024, US-037, US-038, US-039, US-040, US-043, US-044 | J8: Weekly review, accessibility, performance, v1.0 store submission
A9: 8 | B9: 46377 | C9: 46381 | D9: Search and the Shared Spaces foundation: membership, agent permissions, invites, realtime shared lists. | E9: US-053, US-054, US-055, US-056, US-057 | F9: =SUMIFS('Product Backlog'!H2:H68,'Product Backlog'!K2:K68,A9) -> 26 | G9: 30 | H9: =F9/G9 -> 0.86666667 | I9: US-006, US-008, US-012, US-029, US-030 | J9: Spaces foundation, agent permissions, realtime shared lists, search
A10: 9 | B10: 46384 | C10: 46388 | D10: Shared Spaces collaboration and the shared AI agent: assignment, notifications, agent, audit, balancing. | E10: US-058, US-059, US-060, US-061, US-062 | F10: =SUMIFS('Product Backlog'!H2:H68,'Product Backlog'!K2:K68,A10) -> 24 | G10: 30 | H10: =F10/G10 -> 0.8 | I10: US-009, US-010, US-032, US-041, US-055, US-057 | J10: Assignment/comments, space agent, audit log, workload balancing
A11: 10 | B11: 46391 | C11: 46395 | D11: Monetization and extras: billing, tier quotas, calendar, widgets, experimental on-device AI. | E11: US-063, US-064, US-065, US-066, US-067 | F11: =SUMIFS('Product Backlog'!H2:H68,'Product Backlog'!K2:K68,A11) -> 29 | G11: 30 | H11: =F11/G11 -> 0.96666667 | I11: US-006, US-009, US-010, US-013, US-016, US-018, US-020, US-021, US-025 | J11: Billing and tier quotas, calendar, widgets, experimental on-device AI
E13: Sum of sprint points | F13: =SUM(F2:F11) -> 279
E14: Sum of backlog points | F14: =SUM('Product Backlog'!H2:H68) -> 279
E15: Difference (must be 0) | F15: =F13-F14 -> 0
E17: Capacity is an assumption: solo developer with AI coding agents, 1-week sprints. Edit the blue capacity cells to re-check utilization.

Sheet Technical Backlog
A1: Task ID | B1: Category | C1: Task | D1: Epic | E1: Linked Story | F1: Wave | G1: Sprint | H1: Status
A2: TT-01 | B2: Infra | C2: Create GitHub repo, protect main, require CI + 1 review | D2: EP-01 | E2: US-001 | F2: Wave 1 | G2: 1 | H2: Draft
A3: TT-02 | B3: Infra | C3: Provision Supabase dev/staging/prod projects and EAS env | D3: EP-02 | E3: US-005 | F3: Wave 1 | G3: 1 | H3: Draft
A4: TT-03 | B4: Infra | C4: Create EAS project, credentials and build profiles (development/preview/production) | D4: EP-01 | E4: US-002 | F4: Wave 1 | G4: 1 | H4: Draft
A5: TT-04 | B5: DB | C5: Drizzle SQLite schema v1 and migration runner | D5: EP-03 | E5: US-007 | F5: Wave 1 | G5: 1 | H5: Draft
A6: TT-05 | B6: DB | C6: Postgres schema v1 migrations plus RLS policies for profiles | D6: EP-02 | E6: US-005 | F6: Wave 1 | G6: 1 | H6: Draft
A7: TT-06 | B7: DB | C7: Add sync columns and triggers (updated_at, deleted_at, server_seq) | D7: EP-03 | E7: US-029 | F7: Wave 4 | G7: 4 | H7: Draft
A8: TT-07 | B8: DB | C8: pg_cron + pg_net schedule for check-ins and token cleanup | D8: EP-08 | E8: US-033 | F8: Wave 4 | G8: 5 | H8: Draft
A9: TT-08 | B9: DB | C9: Spaces, members, comments, agent_actions tables with RLS | D9: EP-12 | E9: US-054 | F9: Wave 6 | G9: 8 | H9: Draft
A10: TT-09 | B10: API | C10: Edge Function ai-gateway router and provider interface | D10: EP-04 | E10: US-008 | F10: Wave 2 | G10: 1 | H10: Draft
A11: TT-10 | B11: API | C11: Shared Zod schema package used by app and functions | D11: EP-04 | E11: US-010 | F11: Wave 2 | G11: 1 | H11: Draft
A12: TT-11 | B12: API | C12: sync_pull and sync_push RPCs with conflict rules | D12: EP-03 | E12: US-029 | F12: Wave 4 | G12: 4 | H12: Draft
A13: TT-12 | B13: API | C13: revenuecat-webhook function and subscription table | D13: EP-13 | E13: US-063 | F13: Wave 6 | G13: 10 | H13: Draft
... A30: TT-29 | B30: Monitoring | C30: AI cost dashboard (SQL view) with daily spend alert | D30: EP-04 | E30: US-009 | F30: Wave 2 | G30: 1 | H30: Draft

Sheet Architecture & Decisions
A1: Area | B1: Decision | C1: Rationale | D1: Alternatives considered
A2: Client framework | B2: Expo (latest stable SDK) + React Native, TypeScript strict, Expo Router | C2: Fast iteration, OTA updates, one codebase; Expo SDK 56 (May 2026) confirmed stable, SDK 57 is listed on expo.dev/sdk - use latest stable at scaffold | D2: Bare React Native, Flutter
A3: Styling | B3: NativeWind (Tailwind for RN) with token theme | C3: Utility styling, dark mode, fast UI work | D3: StyleSheet only, Tamagui, Unistyles
A4: Client state | B4: Zustand for UI state, TanStack Query for async/server state | C4: Small, predictable, well supported | D4: Redux Toolkit, Jotai
A5: Forms/validation | B5: React Hook Form + Zod (shared schemas) | C5: One schema validates app input and AI output | D5: Formik, Yup
A6: Local database | B6: expo-sqlite + Drizzle ORM | C6: Offline-first, typed queries, FTS5 for search | D6: WatermelonDB, MMKV-only, Realm
A7: Backend platform | B7: Supabase (Postgres, Auth, Realtime, Storage, Edge Functions) | C7: One platform for auth, data, realtime and server code; RLS for isolation | D7: Firebase, custom Node API
A8: Sync | B8: Custom last-write-wins sync over RPC with tombstones (v1); revisit CRDT for Spaces | C8: Simple and testable for single-user data; Spaces need stronger guarantees | D8: PowerSync, ElectricSQL, Replicache
A9: AI provider | B9: Claude via Edge Function gateway; cheaper model for parse/check-ins, stronger model for plan/review/chat | C9: Keys server-side, cost control per route, structured outputs | D9: Direct from client (rejected: key exposure)
A10: AI output safety | B10: JSON-schema validation + one repair retry + typed errors; actions always user-confirmed | C10: Prevents bad data and unsafe actions | D10: Free-text parsing
A11: Voice input | B11: expo-speech-recognition (on-device where available) feeding the same parser; cloud STT only as a later fallback | C11: Free, private, no extra vendor; requires a development build and per-OS locale checks | D11: Cloud STT from day one (cost, privacy)
A12: Photo input | B12: expo-image-picker/camera, resize on device, vision model through the gateway | C12: Reuses the gateway and guardrails | D12: Separate OCR vendor
... A20: On-device AI (experimental) | B20: Evaluate ExecuTorch or llama.rn for offline parse in Phase 3 | C20: Privacy/offline differentiator; needs eval gate | D20: Skip

Sheet Data Model
A1: Entity / Table | B1: Store | C1: Key fields | D1: Relationships | E1: Access (RLS)
A2: profiles | B2: Postgres | C2: id (uuid, = auth.users.id), display_name, timezone, locale, work_start, work_end, daily_capacity_min, buddy_tone, buddy_lang, onboarded_at | D2: 1:1 auth.users | E2: RLS: owner only
A3: tasks | B3: SQLite + Postgres | C3: id (uuidv7), user_id, space_id (nullable), list_id, title, notes, due_at, priority, status, estimate_min, completed_at, postpone_count, source (manual/ai/voice/photo), rrule, parent_task_id, updated_at, deleted_at, server_seq | D3: N:1 lists, N:1 spaces, self-ref parent | E3: RLS: owner or space member by role
A4: subtasks | B4: SQLite + Postgres | C4: id, task_id, title, done, estimate_min, position, updated_at, deleted_at | D4: N:1 tasks | E4: Inherits task access
A5: lists | B5: SQLite + Postgres | C5: id, user_id, space_id, name, color, position, updated_at, deleted_at | D5: 1:N tasks | E5: RLS as tasks
A6: tags / task_tags | B6: SQLite + Postgres | C6: tags(id, user_id, name); task_tags(task_id, tag_id) | D6: M:N tasks-tags | E6: Owner only
A7: plans / plan_blocks | B7: SQLite + Postgres | C7: plans(id, user_id, date, accepted_at, model, prompt_version); plan_blocks(id, plan_id, task_id, start_at, end_at, pinned, reason) | D7: 1:N | E7: Owner only
A8: device_tokens | B8: Postgres | C8: id, user_id, expo_push_token, platform, last_seen_at | D8: N:1 users | E8: Owner only; pruned on invalid receipt
A9: notification_prefs | B9: Postgres | C9: user_id, quiet_start, quiet_end, checkins_enabled, daily_cap | D9: 1:1 users | E9: Owner only
A10: ai_usage_ledger | B10: Postgres | C10: id, user_id, route, model, input_tokens, output_tokens, cost_usd_est, prompt_version, status, created_at | D10: N:1 users | E10: Insert by service role; owner can read own aggregate
A11: weekly_reviews | B11: Postgres | C11: id, user_id, week_start, stats_json, review_json, created_at | D11: N:1 users | E11: Owner only
A12: spaces / space_members | B12: Postgres | C12: spaces(id, name, owner_id, agent_scopes jsonb); space_members(space_id, user_id, role) | D12: M:N users-spaces | E12: RLS: members only
... A16: subscriptions | B16: Postgres | C16: user_id, entitlement, product_id, period_end, store, updated_at | D16: 1:1 users | E16: Webhook writes; owner read

Sheet API Contracts
A1: Endpoint | B1: Method | C1: Description | D1: Request | E1: Response | F1: Auth | G1: Status codes | H1: Story
A2: /functions/v1/ai-gateway/parse | B2: POST | C2: Parse free text into tasks | D2: { text, timezone, now, locale, lists[] } | E2: { tasks: [{ title, dueAt, priority, list, notes, confidence }], promptVersion } | F2: Supabase JWT | G2: 200, 400, 401, 413, 429, 502 | H2: US-016
A3: /functions/v1/ai-gateway/breakdown | B3: POST | C3: Break a task into subtasks | D3: { task: { id, title, notes, dueAt }, maxSubtasks } | E3: { subtasks: [{ title, estimateMin }], totalMin } | F3: Supabase JWT | G3: 200, 400, 401, 429, 502 | H3: US-017
A4: /functions/v1/ai-gateway/plan | B4: POST | C4: Generate a daily plan | D4: { date, timezone, workHours, capacityMin, tasks[], fixedBlocks[] } | E4: { blocks: [{ taskId, startAt, endAt, reason }], unscheduled: [{ taskId, reason }] } | F4: Supabase JWT | G4: 200, 400, 401, 429, 502 | H4: US-020
A5: /functions/v1/ai-gateway/starter-step | B5: POST | C5: Suggest a tiny first step | D5: { task, postponeCount, blockerNote? } | E5: { step, estimateMin, encouragement } | F5: Supabase JWT | G5: 200, 400, 401, 429, 502 | H5: US-035
A6: /functions/v1/ai-gateway/chat | B6: POST (SSE) | C6: Streaming buddy chat with action proposals | D6: { messages[], context: { tasksDigest[] } } | E6: SSE events: text, proposal{ action, args } (never auto-applied) | F6: Supabase JWT | G6: 200, 401, 429, 502 | H6: US-041
A7: /functions/v1/ai-gateway/review | B7: POST | C7: Weekly review narrative | D7: { weekStats, completed[], slipped[] } | E7: { summary, wins[], patterns[], suggestion } | F7: Supabase JWT | G7: 200, 400, 401, 429, 502 | H7: US-047
A8: /functions/v1/ai-gateway/vision-extract | B8: POST | C8: Extract tasks from a photo | D8: { storagePath, timezone } | E8: { tasks[], rawText } | F8: Supabase JWT | G8: 200, 400, 401, 413, 429, 502 | H8: US-044
A9: /functions/v1/ai-gateway/space-agent | B9: POST (SSE) | C9: Shared agent in a space | D9: { spaceId, message } | E9: SSE: text, proposal rows written to agent_actions (pending) | F9: Supabase JWT + space role + agent scope | G9: 200, 401, 403, 429, 502 | H9: US-060
A10: rpc/sync_pull | B10: POST | C10: Fetch changes since a server sequence | D10: { since_seq } | E10: { rows[], next_seq } | F10: Supabase JWT | G10: 200, 401 | H10: US-029
A11: rpc/sync_push | B11: POST | C11: Push local changes | D11: { ops[] } | E11: { accepted[], conflicts[] } | F11: Supabase JWT | G11: 200, 401, 409 | H11: US-029
A12: /functions/v1/send-checkins | B12: POST (cron) | C12: Generate and send check-ins | D12: service-role internal | E12: { sent, skipped } | F12: Service role only | G12: 200 | H12: US-033
... A15: rpc/export_my_data, rpc/delete_my_account | B15: POST | C15: Data export and account deletion | D15: {} | E15: { file } / { ok } | F15: Supabase JWT | G15: 200, 401 | H15: US-039

Sheet QA & Testing
A1: Epic / Feature | B1: Unit | C1: Integration | D1: E2E | E1: Regression | F1: UAT | G1: Edge & error cases | H1: Security cases
A2: EP-01 Foundations | B2: Lint/typecheck rules; helper tests | C2: CI pipeline dry run | D2: Smoke boot on iOS+Android | E2: Run full CI on main nightly | F2: Fresh-clone install on a clean machine | G2: Missing env var fails loudly | H2: No secrets committed (secret scan)
A3: EP-02 Auth | B3: Session store; OTP form validation | C3: Sign in against staging Supabase | D3: Sign in, restart, still signed in | E3: Auth after app update | F3: Sign in with 3 testers | G3: Expired/wrong OTP, no network | H3: RLS cross-user tests; token storage in secure store
A4: EP-03 Task core & sync | B4: Repositories; RRULE edge cases; conflict resolver | C4: SQLite migrations; sync pull/push against staging | D4: Create/complete/delete; two-device sync | E4: Task counts before/after upgrade | F4: Daily use for 1 week | G4: Airplane mode, clock skew, DST, 10k tasks | H4: RLS on tasks; tombstone handling
A5: EP-04 AI gateway | B5: Schema validators; quota math | C5: Gateway with mocked provider | D5: Quick-add happy path | E5: Rate limit and quota behavior | F5: Beta user cost review | G5: Provider timeout, 429, malformed JSON | H5: Injection corpus; key not in bundle; JWT required
A6: EP-05 Capture | B6: Parse result mapping | C6: Parse with golden set | D6: Type sentence, review, save | E6: Eval pass rate vs baseline | F6: 5 testers type real tasks | G6: Ambiguous dates, emoji, 2,000-char input | H6: Prompt isolation
A7: EP-06 Breakdown | B7: Subtask merge logic | C7: Breakdown golden set | D7: Break down, accept some, regenerate | E7: Eval baseline | F7: Testers rate usefulness 1-5 | G7: One-word task, very long task | H7: Output sanitized before render
A8: EP-07 Daily plan | B8: Capacity math, overlap checks | C8: Plan golden set; re-plan | D8: Generate, reorder, accept | E8: Plan constraints never violated | F8: Testers follow a plan for 3 days | G8: No tasks, all tasks overdue, DST day | H8: No other user data in prompt
A9: EP-08 Notifications | B9: Quiet-hours logic | C9: Local schedule; push send to sandbox | D9: Reminder fires; quick action works | E9: Cancel on complete/delete | F9: Real devices over 3 days | G9: Permission denied, token invalid, timezone change | H9: Daily push cap server-side
A10: EP-09 Buddy chat & helper | B10: Proposal parser | C10: Chat with mocked provider | D10: Chat proposes then confirms change | E10: Eval tone/safety set | F10: Testers try 10 prompts | G10: Long history, offline mid-stream | H10: Actions require confirm; injection via task titles
A11: EP-10 Voice & photo | B11: Image resize; locale mapping | C11: Upload and delete job | D11: Speak a task; photo a list | E11: Deletion within 24h | F11: Taglish speakers test | G11: Noisy audio, blurry photo, unsupported locale | H11: Media deletion; consent captured
A12: EP-11 Weekly review | B12: Stats SQL equals JS | C12: Review generation | D12: Open review on Sunday | E12: Numbers match stats | F12: Testers read two reviews | G12: Empty week | H12: No hallucinated numbers
... A15: EP-14 Quality | B15: Eval runner | C15: CI gating | D15: Maestro critical flows | E15: Perf budget checks | F15: Accessibility audit with screen reader | G15: 200% font, low-end Android | H15: PII scrubbing in Sentry

Sheet DevOps & Deploy
A1: Area | B1: Approach
A2: Repository | B2: Single GitHub repo (app + supabase/ functions + migrations + docs); pnpm workspaces for shared packages
A3: Branching | B3: Trunk-based; branches `<type>/tb-<ticket>/<short-kebab-title>`; squash-merge; Conventional Commits `feat(scope): summary (TB-###)`
A4: CI | B4: GitHub Actions: lint, typecheck, unit tests, secret scan, AI evals on prompt/model changes, Maestro on main
A5: CD (app) | B5: EAS Build for native changes; EAS Update (OTA) for JS-only changes via development/preview/production channels; EAS Submit to TestFlight/Play
A6: CD (backend) | B6: Supabase CLI migrations PR -> staging -> prod; Edge Functions deployed from CI
A7: Environments | B7: dev (local + Supabase dev), staging (internal testers), prod; separate Supabase projects and EAS env
A8: Secrets | B8: LLM key and service-role key only in Supabase secrets/CI secrets; never in app bundle
A9: Monitoring | B9: Sentry crashes and release health; Supabase logs; AI cost dashboard with daily spend alert
A10: Logging | B10: Structured logs with request id; no task text in logs; AI requests log metadata only
A11: Backup | B11: Supabase point-in-time recovery enabled on prod; weekly export of ledger tables
A12: Disaster recovery | B12: Restore PITR to new project; OTA rollback to last good update; previous store build kept available; RTO 4h, RPO 15 min (targets)
A13: Release process | B13: Beta weekly; production release after checklist: E2E green, eval baseline met, privacy labels verified

Sheet Risk Register
A1: Risk | B1: Impact | C1: Probability | D1: Mitigation | E1: Owner
A2: AI cost grows faster than revenue | B2: High | C2: Medium | D2: Per-user rate limits and quotas (US-009), cheap model for parse, usage ledger and spend alert, tiered quotas | E2: Owner
A3: Prompt injection or unsafe AI actions | B3: High | C3: Medium | D3: Input caps, schema validation, no server-side action execution, user confirmation, injection corpus in CI | E3: Owner
A4: AI output quality regresses silently | B4: Medium | C4: Medium | D4: Golden sets and CI regression gate (US-025) | E4: Owner
A5: Data loss or duplicates during sync | B5: High | C5: Medium | D5: Tombstones, two-client tests, soft deletes, backups | E5: Owner
A6: App Store rejection (AI disclosure, account deletion, sign-in rules) | B6: Medium | C6: Medium | D6: Compliance stories before release; Sign in with Apple when social sign-in exists | E6: Owner
A7: Solo-capacity slip (velocity below 30) | B7: Medium | C7: High | D7: MVP scope cut order: breakdown, then edit/undo; weekly re-plan of sprints | E7: Owner
A8: Speech recognition quality for Taglish | B8: Medium | C8: Medium | D8: Test locales early; allow typing fallback; evaluate cloud STT fallback | E8: Owner
A9: Cross-space data leak in Shared Spaces | B9: High | C9: Low | D9: RLS tests, agent scope enforcement server-side, isolation tests | E9: Owner
A10: Notification fatigue causes uninstalls | B10: Medium | C10: Medium | D10: Daily cap, quiet hours, user-controlled frequency | E10: Owner
A11: Expo SDK / library breaking changes (e.g. Router migration) | B11: Medium | C11: Medium | D11: Pin versions, upgrade per SDK with a dedicated ticket, use Expo skills for upgrades | E11: Owner
A12: Privacy concerns about sending tasks to an AI provider | B12: Medium | C12: Medium | D12: Clear disclosure, consent, deletion controls, on-device option (US-067) | E12: Owner
A13: Widget/native feature availability differs by platform | B13: Low | C13: Medium | D13: Document per-platform support; ship iOS first | E13: Owner

Sheet Future Improvements
A1: Category | B1: Idea
A2: Nice-to-have | B2: Natural-language search ('what did I plan for the dentist?')
A3: Nice-to-have | B3: Habit streaks and gentle gamification
A4: Scalability | B4: CRDT-based sync for Spaces; move heavy jobs to queues
A5: Performance | B5: Local embeddings for semantic search
A6: Security | B6: E2E encryption option for private lists
A7: AI | B7: Proactive agent that drafts next-day plan overnight
A8: AI | B8: Per-user learned estimation (actual vs estimated time)
A9: Mobile | B9: Apple Watch / Wear OS quick capture
A10: Mobile | B10: Share-sheet extension to create tasks from any app
A11: Mobile | B11: Lock-screen and Live Activity for current task
A12: Integrations | B12: Email-to-task, Google/Outlook calendar sync, Slack
A13: Platform | B13: Public API and automations for Spaces

Sheet PM Import
A1: Level | B1: ID | C1: Parent ID | D1: Issue Type | E1: Summary | F1: Priority | G1: Points | H1: Wave | I1: Workstream | J1: Sprint | K1: Labels
A2: Initiative | B2: TB-INIT | C2: - | D2: Initiative | E2: Task Buddy v1.0 and Shared Spaces | F2: P0 | K2: task-buddy
A3: Epic | B3: EP-01 | C3: TB-INIT | D3: Epic | E3: Foundations & DevOps | F3: P0 | H3: Wave 1 | K3: epic-ep-01
A4: Epic | B4: EP-02 | C4: TB-INIT | D4: Epic | E4: Auth & Accounts | F4: P0 | H4: Wave 1 | K4: epic-ep-02
A5: Epic | B5: EP-03 | C5: TB-INIT | D5: Epic | E5: Task Core & Sync | F5: P0 | H5: Wave 1-4 | K5: epic-ep-03
A6: Epic | B6: EP-04 | C6: TB-INIT | D6: Epic | E6: AI Gateway & Guardrails | F6: P0 | H6: Wave 2 | K6: epic-ep-04
A7: Epic | B7: EP-05 | C7: TB-INIT | D7: Epic | E7: Natural-Language Capture | F7: P0 | H7: Wave 3 | K7: epic-ep-05
A8: Epic | B8: EP-06 | C8: TB-INIT | D8: Epic | E8: AI Task Breakdown | F8: P1 | H8: Wave 3 | K8: epic-ep-06
A9: Epic | B9: EP-07 | C9: TB-INIT | D9: Epic | E9: Smart Daily Plan | F9: P1 | H9: Wave 3-4 | K9: epic-ep-07
A10: Epic | B10: EP-08 | C10: TB-INIT | D10: Epic | E10: Notifications & Buddy Check-ins | F10: P1 | H10: Wave 4 | K10: epic-ep-08
A11: Epic | B11: EP-09 | C11: TB-INIT | D11: Epic | E11: Procrastination Helper & Buddy Chat | F11: P1 | H11: Wave 4-5 | K11: epic-ep-09
A12: Epic | B12: EP-10 | C12: TB-INIT | D12: Epic | E12: Voice & Photo Capture | F12: P1 | H12: Wave 5 | K12: epic-ep-10
A13: Epic | B13: EP-11 | C13: TB-INIT | D13: Epic | E13: Weekly Review & Insights | F13: P2 | H13: Wave 5 | K13: epic-ep-11
A14: Epic | B14: EP-12 | C14: TB-INIT | D14: Epic | E14: Shared Spaces (Multiplayer AI) | F14: P2 | H14: Wave 6 | K14: epic-ep-12
... A16: Epic | B16: EP-14 | C16: TB-INIT | D16: Epic | E16: Quality, Observability & Accessibility | F16: P1 | H16: Wave 3-5 | K16: epic-ep-14
A17: Feature | B17: FT-01 | C17: EP-01 | D17: Feature (label) | E17: Project scaffold & tooling | F17: P0 | K17: feature-ft-01
A18: Feature | B18: FT-02 | C18: EP-01 | D18: Feature (label) | E18: CI/CD & build profiles | F18: P0 | K18: feature-ft-02
A19: Feature | B19: FT-03 | C19: EP-01 | D19: Feature (label) | E19: Design system & navigation shell | F19: P0 | K19: feature-ft-03
A20: Feature | B20: FT-06 | C20: EP-02 | D20: Feature (label) | E20: Supabase backend baseline | F20: P0 | K20: feature-ft-06
A21: Feature | B21: FT-04 | C21: EP-02 | D21: Feature (label) | E21: Email OTP sign-in | F21: P0 | K21: feature-ft-04
A22: Feature | B22: FT-05 | C22: EP-02 | D22: Feature (label) | E22: Social sign-in | F22: P2 | K22: feature-ft-05
A23: Feature | B23: FT-49 | C23: EP-02 | D23: Feature (label) | E23: Settings & preferences | F23: P1 | K23: feature-ft-49
A24: Feature | B24: FT-07 | C24: EP-03 | D24: Feature (label) | E24: Local data layer | F24: P0 | K24: feature-ft-07
A25: Feature | B25: FT-08 | C25: EP-03 | D25: Feature (label) | E25: Task management UI | F25: P0 | K25: feature-ft-08
A26: Feature | B26: FT-09 | C26: EP-03 | D26: Feature (label) | E26: Organization | F26: P2 | K26: feature-ft-09
A27: Feature | B27: FT-10 | C27: EP-03 | D27: Feature (label) | E27: Recurring tasks | F27: P2 | K27: feature-ft-10
A28: Feature | B28: FT-11 | C28: EP-03 | D28: Feature (label) | E28: Offline-first sync | F28: P1 | K28: feature-ft-11
... A65: Feature | B65: FT-48 | C65: EP-14 | D65: Feature (label) | E65: Performance | F65: P2 | K65: feature-ft-48
A66: Story | B66: US-001 | C66: EP-01 | D66: Story | E66: Scaffold Expo app (TypeScript, Router, lint, aliases) | F66: P0 | G66: 3 | H66: Wave 1 | I66: WS-D | J66: 1 | K66: ft-01 mvp
A67: Story | B67: US-002 | C67: EP-01 | D67: Story | E67: CI pipeline and EAS build profiles | F67: P0 | G67: 3 | H67: Wave 1 | I67: WS-D | J67: 1 | K67: ft-02 mvp
A68: Story | B68: US-003 | C68: EP-01 | D68: Story | E68: Design system: theme tokens and UI primitives | F68: P0 | G68: 3 | H68: Wave 1 | I68: WS-A | J68: 1 | K68: ft-03 mvp
A69: Story | B69: US-004 | C69: EP-01 | D69: Story | E69: App shell: tab navigation and task modal | F69: P0 | G69: 2 | H69: Wave 1 | I69: WS-A | J69: 1 | K69: ft-03 mvp
A70: Story | B70: US-005 | C70: EP-02 | D70: Story | E70: Supabase projects, env config and RLS baseline | F70: P0 | G70: 2 | H70: Wave 1 | I70: WS-B | J70: 1 | K70: ft-06 mvp
A71: Story | B71: US-006 | C71: EP-02 | D71: Story | E71: Email OTP sign-in with secure session | F71: P0 | G71: 3 | H71: Wave 1 | I71: WS-B | J71: 1 | K71: ft-04 mvp
A72: Story | B72: US-007 | C72: EP-03 | D72: Story | E72: Local SQLite schema, migrations and repositories | F72: P0 | G72: 3 | H72: Wave 1 | I72: WS-B | J72: 1 | K72: ft-07 mvp
A73: Story | B73: US-008 | C73: EP-04 | D73: Story | E73: AI gateway Edge Function with JWT auth | F73: P0 | G73: 5 | H73: Wave 2 | I73: WS-C | J73: 1 | K73: ft-12 mvp
A74: Story | B74: US-009 | C74: EP-04 | D74: Story | E74: Per-user AI rate limits and token quotas | F74: P0 | G74: 3 | H74: Wave 2 | I74: WS-C | J74: 1 | K74: ft-13 mvp
A75: Story | B75: US-010 | C75: EP-04 | D75: Story | E75: AI output schemas, validation and repair retry | F75: P0 | G75: 3 | H75: Wave 2 | I75: WS-C | J75: 1 | K75: ft-14 mvp
A76: Story | B76: US-011 | C76: EP-04 | D76: Story | E76: Prompt-injection and input hardening | F76: P0 | G76: 2 | H76: Wave 2 | I76: WS-C | J76: 2 | K76: ft-14 mvp
A77: Story | B77: US-012 | C77: EP-03 | D77: Story | E77: Task CRUD with due date and priority | F77: P0 | G77: 5 | H77: Wave 2 | I77: WS-A | J77: 2 | K77: ft-08 mvp
...

Sheet Agile & AI Practices
A1: Practice | B1: Detail
A2: Definition of Ready | B2: AC written and testable; prerequisites done; sized at 8 points or less (split if larger); API contract or screen linked; security/privacy/AI-cost implications noted.
A3: Definition of Done | B3: AC met and demoed; reviewed PR merged with CI green; unit + integration pass (E2E on critical paths); RLS/security tests pass where relevant; AI eval baseline not regressed; no new Sentry errors; docs/tickets note updated; migrations reversible.
A4: Cadence (solo) | B4: Monday: sprint planning (30 pts). Daily: 10-minute self standup. Friday: demo on device + retro + backlog refinement for next sprint.
A5: AI-assisted development | B5: Use coding agents per story: spec from the ticket AC > plan > implement in a branch > run tests > self-review diff > PR. Always attach the ticket doc in docs/tickets/TB-###.md.
A6: Agent model routing | B6: Simple questions and lookups: Sonnet-class. Feature development: Opus-class. Hard or critical work (sync conflict rules, RLS policies, agent scope enforcement, gateway security): top-tier model with a second review pass.
A7: AI-assisted testing | B7: Agents draft unit tests and Maestro flows from AC; human reviews. AI evals (golden sets) gate prompt and model changes in CI.
A8: AI-assisted docs and review | B8: Agents update docs/tickets notes and propose PR summaries; run a code-review pass for security, performance and correctness before human review.
A9: Reuse-first | B9: Before creating a component, hook or utility, check for an existing shared one or pattern; standardize repeated solutions instead of duplicating.
A10: Documentation discipline | B10: CLAUDE.md is updated only when an epic completes or a decision becomes stable and reusable; per-ticket detail lives in docs/tickets/TB-###.md.
A11: Estimation | B11: Fibonacci points; recalibrate velocity after Sprint 2 and re-run the sprint plan.

Sheet Gaps & Assumptions
A1: Topic | B1: Gap / assumption | C1: Impact | D1: Recommendation | E1: Status
A2: Team size and velocity | B2: Assumed solo developer with AI coding agents, 1-week sprints, 30 points per sprint | C2: Sprint dates and MVP-in-2-weeks hinge on this | D2: Confirm; re-run scheduling if velocity differs | E2: Assumption
A3: Sprint 1 start date | B3: Assumed Monday 2026-11-02 | C3: All sprint dates shift | D3: Confirm real start date | E3: Assumption
A4: Target platforms | B4: iOS and Android both in v1.0 | C4: Store work doubles; widgets differ by OS | D4: Confirm; if iOS-first, move Android items out of Wave 5 | E4: Assumption
A5: AI provider and data policy | B5: Claude via gateway; text, audio transcripts and images may be sent to the provider | C5: Drives privacy policy and consent copy | D5: Review provider data-retention terms before beta | E5: Open
A6: Pricing and quotas | B6: Free limits (30 AI calls/hour, daily token cap) and Pro tier price are placeholders | C6: Affects cost model and billing story | D6: Decide after 4 weeks of ledger data | E6: Open
A7: Taglish and Filipino support | B7: Parser and chat expected to handle Taglish; speech recognition locale support unverified per device | C7: Voice accuracy risk | D7: Test fil-PH on target devices in Sprint 6 | E7: Open
A8: Expo SDK version | B8: SDK 56 verified stable (May 2026); SDK 57 listed Jun 2026 on expo.dev/sdk | C8: Library compatibility | D8: Use the latest stable SDK at scaffold time and record it in CLAUDE.md | E8: Open
A9: expo-speech-recognition maintenance | B9: Community library; compatibility table last dated July 2025 | C9: Voice story could slip | D9: Check release status in Sprint 5 before building; fallback is cloud STT | E9: Open
A10: Android widgets | B10: Expo Widgets stability confirmed for iOS only | C10: Widget story scope | D10: Ship iOS widget first; decide Android approach in Phase 3 | E10: Open
A11: NFR targets | B11: Targets assumed: crash-free 99.5%, cold start <2.5s, AI p95 <6s, RTO 4h, RPO 15 min | C11: Test and monitoring thresholds | D11: Confirm or adjust | E11: Assumption
A12: Data retention | B12: Soft-deleted rows purge after 30 days; agent logs 90 days; raw media 24 hours | C12: Compliance and storage | D12: Confirm with privacy policy | E12: Assumption
... A16: Holiday period | B16: Sprints 8-9 fall on 2026-12-21 to 2027-01-01, overlapping Christmas and New Year | C16: Spaces work may slip | D16: Plan lighter capacity or shift Phase 3 start | E16: Assumption
